Workbook

Sheet Executive Summary
A1: CyberArk (CYBR) LBO Model - Executive Summary
A3: Transaction Overview
A4: Target Company | B4: CyberArk Software (CYBR)
A5: Sector | B5: Cybersecurity / Identity Security
A6: FY2025 Revenue ($M) | B6: ='Deal Assumptions'!B22
A7: FY2025 EBITDA ($M) | B7: ='Deal Assumptions'!B23
A8: Revenue Growth (YoY) | B8: 0.36
A10: Deal Parameters
A11: Acquisition Premium | B11: ='Deal Assumptions'!B13
A12: Entry Enterprise Value ($M) | B12: ='Deal Assumptions'!B19
A13: Entry EV/EBITDA | B13: ='Deal Assumptions'!B26
A14: Total Leverage | B14: ='Deal Assumptions'!B29
A15: Sponsor Equity ($M) | B15: ='Deal Assumptions'!B31
A17: Key Return Metrics
A18: Hold Period (Years) | B18: ='Deal Assumptions'!B49
A19: MOIC | B19: ='Returns Analysis'!B15
A20: IRR | B20: ='Returns Analysis'!B16
A22: Data Sources
A23: Model built on CyberArk (CYBR) public financial data: - FY2025 Total Revenue ~$1.361B (+36% YoY), from company FY2025 earnings release - Non-GAAP EBITDA ~$245M (~18% margin), based on company guidance - Total Debt ~$1.22B, Cash ~$1.54B, Net Cash ~$320M - Share Price ~$409, Market Cap ~$20.6B, ~50.6M shares outstanding - ARR ~$1.44B, Subscription Revenue +51% YoY Note: CyberArk has agreed to be acquired by Palo Alto Networks. This model is a hypothetical LBO analysis assuming pre-acquisition scenario.

Sheet Deal Assumptions
A1: CyberArk (CYBR) LBO - Deal Assumptions
A3: Company Name
A4: Company | B4: CyberArk Software Ltd.
A5: Ticker | B5: CYBR (NASDAQ)
A6: Current Share Price ($) | B6: 409
A7: Shares Outstanding (M) | B7: 50.6
A8: Market Cap ($M) | B8: =B6*B7
A9: Existing Net Debt ($M) | B9: -320
A10: Enterprise Value ($M) | B10: =B8+B9
A12: Acquisition Premium & Valuation
A13: Acquisition Premium (%) | B13: 0.3
A14: Acquisition Price/Share ($) | B14: =B6*(1+B13)
A15: Equity Purchase Price ($M) | B15: =B14*B7
A16: Transaction Fees ($M) | B16: 200
A17: Financing Fees ($M) | B17: 300
A18: Total Equity Required ($M) | B18: =B15+B16+B17
A19: Entry Enterprise Value ($M) | B19: =B18-B9
A21: Base Year Financials (FY2025)
A22: Total Revenue ($M) | B22: 1361
A23: Non-GAAP EBITDA ($M) | B23: 245
A24: EBITDA Margin (%) | B24: =B23/B22
A25: Free Cash Flow ($M) | B25: 350
A26: Entry EV/EBITDA (x) | B26: =B19/B23
A28: Financing Structure
A29: Total Leverage (x EBITDA) | B29: 5
A30: Total Debt ($M) | B30: =B29*B23
A31: Equity Contribution ($M) | B31: =B18-B30
A32: Equity Check (%) | B32: =B31/B18
A34: Debt Tranches
A35: Senior Secured (%) | B35: 0.6
A36: Senior Secured Amount ($M) | B36: =B35*B30
A37: Senior Secured Rate (%) | B37: 0.065
A38: Subordinated Notes (%) | B38: 0.4
A39: Subordinated Amount ($M) | B39: =B38*B30
A40: Subordinated Rate (%) | B40: 0.085
A41: Blended Rate (%) | B41: =B35*B37+B38*B40
A43: Amortization Assumptions
A44: Senior Mandatory Amort (%) | B44: 0.05
A45: Cash Sweep (%) | B45: 0.5
A46: Subordinated Amort | B46: 0
...

Sheet Sources & Uses
A1: Sources & Uses
A3: Sources | B3: Amount ($M)
A4: Senior Secured Debt | B4: ='Deal Assumptions'!B36
A5: Subordinated Notes | B5: ='Deal Assumptions'!B39
A6: Sponsor Equity | B6: ='Deal Assumptions'!B31
A7: Total Sources | B7: =B4+B5+B6
A9: Uses | B9: Amount ($M)
A10: Equity Purchase Price | B10: ='Deal Assumptions'!B15
A11: Transaction Fees | B11: ='Deal Assumptions'!B16
A12: Financing Fees | B12: ='Deal Assumptions'!B17
A13: Repay Existing Net Debt | B13: =-'Deal Assumptions'!B9
A14: Total Uses | B14: =B10+B11+B12+B13
A16: Balance Check (should = 0) | B16: =B7-B14

Sheet Operating Model
A1: Operating Model - 5-Year Projections
A2: Metric | B2: Base (FY2025) | C2: Year 1 | D2: Year 2 | E2: Year 3 | F2: Year 4 | G2: Year 5 | H2: CAGR
A4: Total Revenue ($M) | B4: ='Deal Assumptions'!B22 | C4: =B4*(1+'Deal Assumptions'!B53) | D4: =C4*(1+'Deal Assumptions'!B53) | E4: =D4*(1+'Deal Assumptions'!B54) | F4: =E4*(1+'Deal Assumptions'!B54) | G4: =F4*(1+'Deal Assumptions'!B54) | H4: =(G4/B4)^(1/5)-1
A5: Revenue Growth (%) | B5: N/A | C5: =C4/B4-1 | D5: =D4/C4-1 | E5: =E4/D4-1 | F5: =F4/E4-1 | G5: =G4/F4-1 | H5: =H4
A7: EBITDA ($M) | B7: ='Deal Assumptions'!B23 | C7: =C4*'Deal Assumptions'!B55 | D7: =D4*'Deal Assumptions'!B55 | E7: =E4*'Deal Assumptions'!B56 | F7: =F4*'Deal Assumptions'!B56 | G7: =G4*'Deal Assumptions'!B56
A8: EBITDA Margin (%) | B8: =B7/B4 | C8: =C7/C4 | D8: =D7/D4 | E8: =E7/E4 | F8: =F7/F4 | G8: =G7/G4
A10: Depreciation & Amortization ($M) | B10: =B4*'Deal Assumptions'!B59 | C10: =C4*'Deal Assumptions'!B59 | D10: =D4*'Deal Assumptions'!B59 | E10: =E4*'Deal Assumptions'!B59 | F10: =F4*'Deal Assumptions'!B59 | G10: =G4*'Deal Assumptions'!B59
A11: EBIT ($M) | B11: =B7-B10 | C11: =C7-C10 | D11: =D7-D10 | E11: =E7-E10 | F11: =F7-F10 | G11: =G7-G10
A12: Taxes ($M) | B12: =MAX(0,B11*'Deal Assumptions'!B58) | C12: =MAX(0,C11*'Deal Assumptions'!B58) | D12: =MAX(0,D11*'Deal Assumptions'!B58) | E12: =MAX(0,E11*'Deal Assumptions'!B58) | F12: =MAX(0,F11*'Deal Assumptions'!B58) | G12: =MAX(0,G11*'Deal Assumptions'!B58)
A13: NOPAT ($M) | B13: =B11-B12 | C13: =C11-C12 | D13: =D11-D12 | E13: =E11-E12 | F13: =F11-F12 | G13: =G11-G12
A15: Capital Expenditure ($M) | B15: =B4*'Deal Assumptions'!B57 | C15: =C4*'Deal Assumptions'!B57 | D15: =D4*'Deal Assumptions'!B57 | E15: =E4*'Deal Assumptions'!B57 | F15: =F4*'Deal Assumptions'!B57 | G15: =G4*'Deal Assumptions'!B57
A16: Change in NWC ($M) | B16: 0 | C16: =(C4-B4)*'Deal Assumptions'!B60 | D16: =(D4-C4)*'Deal Assumptions'!B60 | E16: =(E4-D4)*'Deal Assumptions'!B60 | F16: =(F4-E4)*'Deal Assumptions'!B60 | G16: =(G4-F4)*'Deal Assumptions'!B60
A18: Unlevered FCF ($M) | B18: =B13+B10-B15-B16 | C18: =C13+C10-C15-C16 | D18: =D13+D10-D15-D16 | E18: =E13+E10-E15-E16 | F18: =F13+F10-F15-F16 | G18: =G13+G10-G15-G16

Sheet Debt Schedule
A1: Debt Schedule
A2: Metric | B2: Closing | C2: Year 1 | D2: Year 2 | E2: Year 3 | F2: Year 4 | G2: Year 5
A4: Senior Secured Debt
A5: Beginning Balance ($M) | B5: ='Deal Assumptions'!B36 | C5: =B8 | D5: =C8 | E5: =D8 | F5: =E8 | G5: =F8
A6: Mandatory Amortization ($M) | B6: 0 | C6: ='Deal Assumptions'!B36*'Deal Assumptions'!B44 | D6: ='Deal Assumptions'!B36*'Deal Assumptions'!B44 | E6: ='Deal Assumptions'!B36*'Deal Assumptions'!B44 | F6: ='Deal Assumptions'!B36*'Deal Assumptions'!B44 | G6: ='Deal Assumptions'!B36*'Deal Assumptions'!B44
A7: Cash Sweep ($M) | B7: 0 | C7: =MAX(0,('Operating Model'!C18-C9-C6)*'Deal Assumptions'!B45) | D7: =MAX(0,('Operating Model'!D18-D9-D6)*'Deal Assumptions'!B45) | E7: =MAX(0,('Operating Model'!E18-E9-E6)*'Deal Assumptions'!B45) | F7: =MAX(0,('Operating Model'!F18-F9-F6)*'Deal Assumptions'!B45) | G7: =MAX(0,('Operating Model'!G18-G9-G6)*'Deal Assumptions'!B45)
A8: Ending Balance ($M) | B8: =B5-B6-B7 | C8: =MAX(0,C5-C6-C7) | D8: =MAX(0,D5-D6-D7) | E8: =MAX(0,E5-E6-E7) | F8: =MAX(0,F5-F6-F7) | G8: =MAX(0,G5-G6-G7)
A9: Interest Expense ($M) | B9: 0 | C9: =C5*'Deal Assumptions'!B37 | D9: =D5*'Deal Assumptions'!B37 | E9: =E5*'Deal Assumptions'!B37 | F9: =F5*'Deal Assumptions'!B37 | G9: =G5*'Deal Assumptions'!B37
A11: Subordinated Notes
A12: Beginning Balance ($M) | B12: ='Deal Assumptions'!B39 | C12: =B15 | D12: =C15 | E12: =D15 | F12: =E15 | G12: =F15
A13: Mandatory Amortization ($M) | B13: 0 | C13: 0 | D13: 0 | E13: 0 | F13: 0 | G13: 0
A14: Cash Sweep ($M) | B14: 0 | C14: 0 | D14: 0 | E14: 0 | F14: 0 | G14: 0
A15: Ending Balance ($M) | B15: =B12 | C15: =C12-C13-C14 | D15: =D12-D13-D14 | E15: =E12-E13-E14 | F15: =F12-F13-F14 | G15: =G12-G13-G14
A16: Interest Expense ($M) | B16: 0 | C16: =C12*'Deal Assumptions'!B40 | D16: =D12*'Deal Assumptions'!B40 | E16: =E12*'Deal Assumptions'!B40 | F16: =F12*'Deal Assumptions'!B40 | G16: =G12*'Deal Assumptions'!B40
A18: Total Debt Summary
A19: Total Beginning Debt ($M) | B19: =B5+B12 | C19: =C5+C12 | D19: =D5+D12 | E19: =E5+E12 | F19: =F5+F12 | G19: =G5+G12
A20: Total Ending Debt ($M) | B20: =B8+B15 | C20: =C8+C15 | D20: =D8+D15 | E20: =E8+E15 | F20: =F8+F15 | G20: =G8+G15
A21: Total Interest Expense ($M) | B21: =B9+B16 | C21: =C9+C16 | D21: =D9+D16 | E21: =E9+E16 | F21: =F9+F16 | G21: =G9+G16
A22: Leverage Ratio (x EBITDA) | B22: ='Deal Assumptions'!B29 | C22: =IF('Operating Model'!C7>0,C19/'Operating Model'!C7,0) | D22: =IF('Operating Model'!D7>0,D19/'Operating Model'!D7,0) | E22: =IF('Operating Model'!E7>0,E19/'Operating Model'!E7,0) | F22: =IF('Operating Model'!F7>0,F19/'Operating Model'!F7,0) | G22: =IF('Operating Model'!G7>0,G19/'Operating Model'!G7,0)
A24: Exit Net Debt (Year 5, $M) | G24: =G20

Sheet Returns Analysis
A1: Returns Analysis
A3: Exit Valuation
A4: Exit Year EBITDA ($M) | B4: ='Operating Model'!G7
A5: Exit EV/EBITDA (x) | B5: ='Deal Assumptions'!B50
A6: Exit Enterprise Value ($M) | B6: =B4*B5
A7: Less: Exit Net Debt ($M) | B7: ='Debt Schedule'!G20
A8: Exit Equity Value ($M) | B8: =B6-B7
A10: Cash Flow Waterfall
A11: Initial Equity Investment ($M) | B11: =-'Deal Assumptions'!B31
A12: Exit Equity Proceeds ($M) | B12: =B8
A14: Return Metrics
A15: MOIC (Multiple of Invested Capital) | B15: =B12/-B11
A16: IRR (%) | B16: =(B12/-B11)^(1/'Deal Assumptions'!B49)-1
A18: Hold Period (Years) | B18: ='Deal Assumptions'!B49
A19: Equity Invested ($M) | B19: =-B11
A20: Exit Equity Value ($M) | B20: =B12
A21: Gross Profit ($M) | B21: =B12+B11
A23: Entry vs Exit Comparison
A24: Entry EV/EBITDA (x) | B24: ='Deal Assumptions'!B26
A25: Exit EV/EBITDA (x) | B25: ='Deal Assumptions'!B50
A26: Multiple Expansion/Contraction | B26: =B25/B24-1
A27: EBITDA Growth (x) | B27: =B4/'Deal Assumptions'!B23
A28: Debt Paydown ($M) | B28: ='Debt Schedule'!B20-'Debt Schedule'!G20

Sheet Sensitivity Analysis
A1: Sensitivity Analysis (5x5)
A3: IRR Sensitivity (%)
A4: Exit Mult \ Growth Adj | B4: -4% | C4: -2% | D4: Base | E4: +2% | F4: +4%
A5: 18x | B5: 0.042875691 | C5: 0.069436765 | D5: 0.093594493 | E5: 0.1157889 | F5: 0.13634618
A6: 20x | B6: 0.06661367 | C6: 0.093594493 | D6: 0.11814877 | E6: 0.14071836 | F6: 0.16163136
A7: 22x | B7: 0.088409164 | C7: 0.1157889 | D7: 0.14071836 | E7: 0.16364173 | F7: 0.18488931
A8: 24x | B8: 0.10858691 | C8: 0.13634618 | D8: 0.16163136 | E8: 0.18488931 | F8: 0.20645269
A9: 26x | B9: 0.12739432 | C9: 0.15551526 | D9: 0.18113853 | E9: 0.20471384 | F9: 0.2265763
A12: MOIC Sensitivity (x)
A13: Exit Mult \ Growth Adj | B13: -4% | C13: -2% | D13: Base | E13: +2% | F13: +4%
A14: 18x | B14: 1.2335669 | C14: 1.3988642 | D14: 1.5641614 | E14: 1.7294587 | F14: 1.8947559
A15: 20x | B15: 1.3804978 | C15: 1.5641614 | D15: 1.747825 | E15: 1.9314886 | F15: 2.1151522
A16: 22x | B16: 1.5274287 | C16: 1.7294587 | D16: 1.9314886 | E16: 2.1335186 | F16: 2.3355486
A17: 24x | B17: 1.6743596 | C17: 1.8947559 | D17: 2.1151522 | E17: 2.3355486 | F17: 2.5559449
A18: 26x | B18: 1.8212905 | C18: 2.0600532 | D18: 2.2988159 | E18: 2.5375785 | F18: 2.7763412
